[2022-06-20 08:57:48] [INFO] [process-244] [thread-17488] [__main__-manage.py:29] Run api server...
[2022-06-20 08:57:48] [INFO] [process-244] [thread-17488] [__main__-manage.py:31] bind ip is http://0.0.0.0:8080
[2022-06-20 08:57:51] [INFO] [process-244] [thread-17488] [uvicorn.error-server.py:75] Started server process [244]
[2022-06-20 08:57:51] [INFO] [process-244] [thread-17488] [uvicorn.error-on.py:45] Waiting for application startup.
[2022-06-20 08:57:51] [INFO] [process-244] [thread-17488] [uvicorn.error-on.py:59] Application startup complete.
[2022-06-20 08:57:51] [INFO] [process-244] [thread-17488] [uvicorn.error-server.py:206] Uvicorn running on http://0.0.0.0:8080 (Press CTRL+C to quit)
[2022-06-20 08:57:54] [INFO] [process-244] [thread-17488] [app.fastapi_app-fastapi_app.py:27] start call user_define_middleware
[2022-06-20 08:57:55] [ERROR] [process-244] [thread-17488] [asyncio-base_events.py:1707] Exception in callback <TaskWakeupMethWrapper object at 0x000001F27C4AF670>(<Future finished result=None>)
handle: <Handle <TaskWakeupMethWrapper object at 0x000001F27C4AF670>(<Future finished result=None>)>
Traceback (most recent call last):
  File "c:\python3.8\lib\asyncio\events.py", line 81, in _run
    self._context.run(self._callback, *self._args)
RuntimeError: Cannot enter into task <Task pending name='Task-1' coro=<Server.serve() running at D:\vir_env\graph\lib\site-packages\uvicorn\server.py:80> wait_for=<Future finished result=None> cb=[_run_until_complete_cb() at c:\python3.8\lib\asyncio\base_events.py:184]> while another task <Task pending name='starlette.middleware.base.BaseHTTPMiddleware.__call__.<locals>.call_next.<locals>.coro' coro=<BaseHTTPMiddleware.__call__.<locals>.call_next.<locals>.coro() running at D:\vir_env\graph\lib\site-packages\starlette\middleware\base.py:36> cb=[TaskGroup._spawn.<locals>.task_done() at D:\vir_env\graph\lib\site-packages\anyio\_backends\_asyncio.py:629]> is being executed.
[2022-06-20 08:57:56] [ERROR] [process-244] [thread-17488] [uvicorn.error-httptools_impl.py:375] Exception in ASGI application
Traceback (most recent call last):
  File "D:\vir_env\graph\lib\site-packages\aiomysql\connection.py", line 486, in _connect
    self._reader, self._writer = await \
  File "c:\python3.8\lib\asyncio\tasks.py", line 455, in wait_for
    return await fut
  File "c:\python3.8\lib\asyncio\streams.py", line 52, in open_connection
    transport, _ = await loop.create_connection(
  File "c:\python3.8\lib\asyncio\base_events.py", line 1025, in create_connection
    raise exceptions[0]
  File "c:\python3.8\lib\asyncio\base_events.py", line 1010, in create_connection
    sock = await self._connect_sock(
  File "c:\python3.8\lib\asyncio\base_events.py", line 924, in _connect_sock
    await self.sock_connect(sock, address)
  File "c:\python3.8\lib\asyncio\proactor_events.py", line 702, in sock_connect
    return await self._proactor.connect(sock, address)
  File "c:\python3.8\lib\asyncio\tasks.py", line 349, in __wakeup
    future.result()
  File "c:\python3.8\lib\asyncio\windows_events.py", line 808, in _poll
    value = callback(transferred, key, ov)
  File "c:\python3.8\lib\asyncio\windows_events.py", line 595, in finish_connect
    ov.getresult()
ConnectionRefusedError: [WinError 1225] Ô¶³Ì¼ÆËã»ú¾Ü¾øÍøÂçÁ¬½Ó¡£

The above exception was the direct cause of the following exception:

Traceback (most recent call last):
  File "D:\vir_env\graph\lib\site-packages\uvicorn\protocols\http\httptools_impl.py", line 372, in run_asgi
    result = await app(self.scope, self.receive, self.send)
  File "D:\vir_env\graph\lib\site-packages\uvicorn\middleware\proxy_headers.py", line 75, in __call__
    return await self.app(scope, receive, send)
  File "D:\vir_env\graph\lib\site-packages\fastapi\applications.py", line 269, in __call__
    await super().__call__(scope, receive, send)
  File "D:\vir_env\graph\lib\site-packages\starlette\applications.py", line 124, in __call__
    await self.middleware_stack(scope, receive, send)
  File "D:\vir_env\graph\lib\site-packages\starlette\middleware\errors.py", line 184, in __call__
    raise exc
  File "D:\vir_env\graph\lib\site-packages\starlette\middleware\errors.py", line 162, in __call__
    await self.app(scope, receive, _send)
  File "D:\vir_env\graph\lib\site-packages\starlette\middleware\base.py", line 68, in __call__
    response = await self.dispatch_func(request, call_next)
  File "Z:\ÖÇÄÜËÑË÷\search_engine_sdk\Tasks\anydata_search\app\fastapi_app.py", line 28, in user_define_middleware
    response = await call_next(request)
  File "D:\vir_env\graph\lib\site-packages\starlette\middleware\base.py", line 46, in call_next
    raise app_exc
  File "D:\vir_env\graph\lib\site-packages\starlette\middleware\base.py", line 36, in coro
    await self.app(scope, request.receive, send_stream.send)
  File "D:\vir_env\graph\lib\site-packages\starlette\exceptions.py", line 93, in __call__
    raise exc
  File "D:\vir_env\graph\lib\site-packages\starlette\exceptions.py", line 82, in __call__
    await self.app(scope, receive, sender)
  File "D:\vir_env\graph\lib\site-packages\fastapi\middleware\asyncexitstack.py", line 21, in __call__
    raise e
  File "D:\vir_env\graph\lib\site-packages\fastapi\middleware\asyncexitstack.py", line 18, in __call__
    await self.app(scope, receive, send)
  File "D:\vir_env\graph\lib\site-packages\starlette\routing.py", line 670, in __call__
    await route.handle(scope, receive, send)
  File "D:\vir_env\graph\lib\site-packages\starlette\routing.py", line 266, in handle
    await self.app(scope, receive, send)
  File "D:\vir_env\graph\lib\site-packages\starlette\routing.py", line 65, in app
    response = await func(request)
  File "D:\vir_env\graph\lib\site-packages\fastapi\routing.py", line 227, in app
    raw_response = await run_endpoint_function(
  File "D:\vir_env\graph\lib\site-packages\fastapi\routing.py", line 160, in run_endpoint_function
    return await dependant.call(**values)
  File "Z:\ÖÇÄÜËÑË÷\search_engine_sdk\Tasks\anydata_search\app\services\search.py", line 46, in post
    conf_info = await get_adv_conf(ids=conf_content.kg_ids, ids_type="test", conf_content=conf_content.conf_content)
  File "Z:\ÖÇÄÜËÑË÷\search_engine_sdk\Tasks\anydata_search\app\utils\get_adv_config.py", line 82, in get_adv_conf
    mysql_connector = inject.instance(AsyncRequestMysql)
  File "D:\vir_env\graph\lib\site-packages\inject\__init__.py", line 402, in instance
    return get_injector_or_die().get_instance(cls)
  File "D:\vir_env\graph\lib\site-packages\inject\__init__.py", line 217, in get_instance
    return binding()
  File "D:\vir_env\graph\lib\site-packages\inject\__init__.py", line 264, in __call__
    self._instance = self._constructor()
  File "D:\vir_env\graph\lib\site-packages\inject\__init__.py", line 342, in injection_wrapper
    return sync_func(*args, **kwargs)
  File "Z:\ÖÇÄÜËÑË÷\search_engine_sdk\Tasks\anydata_search\app\dependencies.py", line 64, in init_mysql_db
    pool = loop.run_until_complete(aiomysql.create_pool(
  File "D:\vir_env\graph\lib\site-packages\nest_asyncio.py", line 89, in run_until_complete
    return f.result()
  File "c:\python3.8\lib\asyncio\futures.py", line 178, in result
    raise self._exception
  File "c:\python3.8\lib\asyncio\tasks.py", line 282, in __step
    result = coro.throw(exc)
  File "D:\vir_env\graph\lib\site-packages\aiomysql\utils.py", line 17, in throw
    return self._coro.throw(typ)
  File "D:\vir_env\graph\lib\site-packages\aiomysql\pool.py", line 29, in _create_pool
    await pool._fill_free_pool(False)
  File "D:\vir_env\graph\lib\site-packages\aiomysql\pool.py", line 167, in _fill_free_pool
    conn = await connect(echo=self._echo, loop=self._loop,
  File "D:\vir_env\graph\lib\site-packages\aiomysql\connection.py", line 75, in _connect
    await conn._connect()
  File "D:\vir_env\graph\lib\site-packages\aiomysql\connection.py", line 521, in _connect
    raise OperationalError(2003,
pymysql.err.OperationalError: (2003, "Can't connect to MySQL server on '10.2.196.57'")
[2022-06-20 08:58:27] [INFO] [process-244] [thread-17488] [app.fastapi_app-fastapi_app.py:27] start call user_define_middleware
[2022-06-20 08:58:28] [INFO] [process-244] [thread-17488] [root-ConnectionPool.py:176] Get connection to ('10.4.131.25', 9669)
[2022-06-20 08:58:28] [INFO] [process-244] [thread-17488] [root-ConnectionPool.py:163] Get connection to ('10.4.131.25', 9669)
[2022-06-20 08:58:28] [INFO] [process-244] [thread-17488] [app.fastapi_app-fastapi_app.py:29] end process user_define_middleware
[2022-08-26 17:48:57] [INFO] [process-30976] [thread-31708] [__main__-manager.py:29] Run api server...
[2022-08-26 17:48:57] [INFO] [process-30976] [thread-31708] [__main__-manager.py:31] bind ip is http://0.0.0.0:8080
[2022-08-26 17:49:40] [INFO] [process-30512] [thread-7800] [__main__-manager.py:29] Run api server...
[2022-08-26 17:49:40] [INFO] [process-30512] [thread-7800] [__main__-manager.py:31] bind ip is http://0.0.0.0:8080
[2022-08-26 17:50:57] [INFO] [process-29940] [thread-12456] [__main__-manager.py:29] Run api server...
[2022-08-26 17:50:57] [INFO] [process-29940] [thread-12456] [__main__-manager.py:31] bind ip is http://0.0.0.0:8080
[2022-08-26 17:51:20] [INFO] [process-26320] [thread-2260] [__main__-manager.py:29] Run api server...
[2022-08-26 17:51:20] [INFO] [process-26320] [thread-2260] [__main__-manager.py:31] bind ip is http://0.0.0.0:8080
[2022-08-26 17:51:21] [INFO] [process-26320] [thread-2260] [uvicorn.error-server.py:75] Started server process [26320]
[2022-08-26 17:51:21] [INFO] [process-26320] [thread-2260] [uvicorn.error-on.py:45] Waiting for application startup.
[2022-08-26 17:51:21] [INFO] [process-26320] [thread-2260] [uvicorn.error-on.py:59] Application startup complete.
[2022-08-26 17:51:21] [INFO] [process-26320] [thread-2260] [uvicorn.error-server.py:206] Uvicorn running on http://0.0.0.0:8080 (Press CTRL+C to quit)
[2022-08-26 17:52:03] [INFO] [process-26320] [thread-2260] [uvicorn.error-server.py:252] Shutting down
[2022-08-26 17:52:03] [INFO] [process-26320] [thread-2260] [uvicorn.error-on.py:64] Waiting for application shutdown.
[2022-08-26 17:52:03] [INFO] [process-26320] [thread-2260] [uvicorn.error-on.py:75] Application shutdown complete.
[2022-08-26 17:52:03] [INFO] [process-26320] [thread-2260] [uvicorn.error-server.py:85] Finished server process [26320]
[2022-08-26 17:52:05] [INFO] [process-12640] [thread-30860] [__main__-manager.py:29] Run api server...
[2022-08-26 17:52:05] [INFO] [process-12640] [thread-30860] [__main__-manager.py:31] bind ip is http://0.0.0.0:8080
[2022-08-26 17:52:06] [INFO] [process-12640] [thread-30860] [uvicorn.error-server.py:75] Started server process [12640]
[2022-08-26 17:52:06] [INFO] [process-12640] [thread-30860] [uvicorn.error-on.py:45] Waiting for application startup.
[2022-08-26 17:52:06] [INFO] [process-12640] [thread-30860] [uvicorn.error-on.py:59] Application startup complete.
[2022-08-26 17:52:06] [INFO] [process-12640] [thread-30860] [uvicorn.error-server.py:206] Uvicorn running on http://0.0.0.0:8080 (Press CTRL+C to quit)
[2022-08-26 17:52:07] [INFO] [process-12640] [thread-30860] [uvicorn.error-server.py:252] Shutting down
[2022-08-26 17:52:07] [INFO] [process-12640] [thread-30860] [uvicorn.error-on.py:64] Waiting for application shutdown.
[2022-08-26 17:52:07] [INFO] [process-12640] [thread-30860] [uvicorn.error-on.py:75] Application shutdown complete.
[2022-08-26 17:52:07] [INFO] [process-12640] [thread-30860] [uvicorn.error-server.py:85] Finished server process [12640]
[2022-08-26 17:52:07] [INFO] [process-19036] [thread-28148] [__main__-manager.py:29] Run api server...
[2022-08-26 17:52:07] [INFO] [process-19036] [thread-28148] [__main__-manager.py:31] bind ip is http://0.0.0.0:8080
[2022-08-26 17:52:09] [INFO] [process-19036] [thread-28148] [uvicorn.error-server.py:75] Started server process [19036]
[2022-08-26 17:52:09] [INFO] [process-19036] [thread-28148] [uvicorn.error-on.py:45] Waiting for application startup.
[2022-08-26 17:52:09] [INFO] [process-19036] [thread-28148] [uvicorn.error-on.py:59] Application startup complete.
[2022-08-26 17:52:09] [INFO] [process-19036] [thread-28148] [uvicorn.error-server.py:206] Uvicorn running on http://0.0.0.0:8080 (Press CTRL+C to quit)
[2022-08-26 17:53:26] [INFO] [process-19036] [thread-28148] [app.fastapi_app-fastapi_app.py:28] start call user_define_middleware
[2022-08-26 17:53:27] [ERROR] [process-19036] [thread-28148] [uvicorn.error-httptools_impl.py:375] Exception in ASGI application
Traceback (most recent call last):
  File "C:\Users\Brooks.he\PycharmProjects\graphengine-alg-server-general\venv\lib\site-packages\aiohttp\connector.py", line 1001, in _create_direct_connection
    hosts = await asyncio.shield(host_resolved)
  File "C:\Python3.8\lib\asyncio\futures.py", line 260, in __await__
    yield self  # This tells Task to wait for completion.
  File "C:\Python3.8\lib\asyncio\tasks.py", line 349, in __wakeup
    future.result()
  File "C:\Python3.8\lib\asyncio\futures.py", line 178, in result
    raise self._exception
  File "C:\Python3.8\lib\asyncio\tasks.py", line 282, in __step
    result = coro.throw(exc)
  File "C:\Users\Brooks.he\PycharmProjects\graphengine-alg-server-general\venv\lib\site-packages\aiohttp\connector.py", line 867, in _resolve_host
    addrs = await self._resolver.resolve(host, port, family=self._family)
  File "C:\Users\Brooks.he\PycharmProjects\graphengine-alg-server-general\venv\lib\site-packages\aiohttp\resolver.py", line 31, in resolve
    infos = await self._loop.getaddrinfo(
  File "C:\Python3.8\lib\asyncio\base_events.py", line 825, in getaddrinfo
    return await self.run_in_executor(
  File "C:\Python3.8\lib\asyncio\futures.py", line 260, in __await__
    yield self  # This tells Task to wait for completion.
  File "C:\Python3.8\lib\asyncio\tasks.py", line 349, in __wakeup
    future.result()
  File "C:\Python3.8\lib\asyncio\futures.py", line 178, in result
    raise self._exception
  File "C:\Python3.8\lib\concurrent\futures\thread.py", line 57, in run
    result = self.fn(*self.args, **self.kwargs)
  File "C:\Python3.8\lib\socket.py", line 918, in getaddrinfo
    for res in _socket.getaddrinfo(host, port, family, type, proto, flags):
socket.gaierror: [Errno 11001] getaddrinfo failed

The above exception was the direct cause of the following exception:

Traceback (most recent call last):
  File "C:\Users\Brooks.he\PycharmProjects\graphengine-alg-server-general\venv\lib\site-packages\uvicorn\protocols\http\httptools_impl.py", line 372, in run_asgi
    result = await app(self.scope, self.receive, self.send)
  File "C:\Users\Brooks.he\PycharmProjects\graphengine-alg-server-general\venv\lib\site-packages\uvicorn\middleware\proxy_headers.py", line 75, in __call__
    return await self.app(scope, receive, send)
  File "C:\Users\Brooks.he\PycharmProjects\graphengine-alg-server-general\venv\lib\site-packages\fastapi\applications.py", line 269, in __call__
    await super().__call__(scope, receive, send)
  File "C:\Users\Brooks.he\PycharmProjects\graphengine-alg-server-general\venv\lib\site-packages\starlette\applications.py", line 124, in __call__
    await self.middleware_stack(scope, receive, send)
  File "C:\Users\Brooks.he\PycharmProjects\graphengine-alg-server-general\venv\lib\site-packages\starlette\middleware\errors.py", line 184, in __call__
    raise exc
  File "C:\Users\Brooks.he\PycharmProjects\graphengine-alg-server-general\venv\lib\site-packages\starlette\middleware\errors.py", line 162, in __call__
    await self.app(scope, receive, _send)
  File "C:\Users\Brooks.he\PycharmProjects\graphengine-alg-server-general\venv\lib\site-packages\starlette\middleware\base.py", line 68, in __call__
    response = await self.dispatch_func(request, call_next)
  File "C:\Users\Brooks.he\PycharmProjects\graphengine-alg-server-general\app\fastapi_app.py", line 29, in user_define_middleware
    response = await call_next(request)
  File "C:\Users\Brooks.he\PycharmProjects\graphengine-alg-server-general\venv\lib\site-packages\starlette\middleware\base.py", line 46, in call_next
    raise app_exc
  File "C:\Users\Brooks.he\PycharmProjects\graphengine-alg-server-general\venv\lib\site-packages\starlette\middleware\base.py", line 36, in coro
    await self.app(scope, request.receive, send_stream.send)
  File "C:\Users\Brooks.he\PycharmProjects\graphengine-alg-server-general\venv\lib\site-packages\starlette\exceptions.py", line 93, in __call__
    raise exc
  File "C:\Users\Brooks.he\PycharmProjects\graphengine-alg-server-general\venv\lib\site-packages\starlette\exceptions.py", line 82, in __call__
    await self.app(scope, receive, sender)
  File "C:\Users\Brooks.he\PycharmProjects\graphengine-alg-server-general\venv\lib\site-packages\fastapi\middleware\asyncexitstack.py", line 21, in __call__
    raise e
  File "C:\Users\Brooks.he\PycharmProjects\graphengine-alg-server-general\venv\lib\site-packages\fastapi\middleware\asyncexitstack.py", line 18, in __call__
    await self.app(scope, receive, send)
  File "C:\Users\Brooks.he\PycharmProjects\graphengine-alg-server-general\venv\lib\site-packages\starlette\routing.py", line 670, in __call__
    await route.handle(scope, receive, send)
  File "C:\Users\Brooks.he\PycharmProjects\graphengine-alg-server-general\venv\lib\site-packages\starlette\routing.py", line 266, in handle
    await self.app(scope, receive, send)
  File "C:\Users\Brooks.he\PycharmProjects\graphengine-alg-server-general\venv\lib\site-packages\starlette\routing.py", line 65, in app
    response = await func(request)
  File "C:\Users\Brooks.he\PycharmProjects\graphengine-alg-server-general\venv\lib\site-packages\fastapi\routing.py", line 227, in app
    raw_response = await run_endpoint_function(
  File "C:\Users\Brooks.he\PycharmProjects\graphengine-alg-server-general\venv\lib\site-packages\fastapi\routing.py", line 160, in run_endpoint_function
    return await dependant.call(**values)
  File "C:\Users\Brooks.he\PycharmProjects\graphengine-alg-server-general\app\services\search.py", line 63, in post
    result_of_one_kg = await task
  File "C:\Python3.8\lib\asyncio\futures.py", line 260, in __await__
    yield self  # This tells Task to wait for completion.
  File "C:\Python3.8\lib\asyncio\tasks.py", line 349, in __wakeup
    future.result()
  File "C:\Python3.8\lib\asyncio\futures.py", line 178, in result
    raise self._exception
  File "C:\Python3.8\lib\asyncio\tasks.py", line 280, in __step
    result = coro.send(None)
  File "C:\Users\Brooks.he\PycharmProjects\graphengine-alg-server-general\app\handlers\search_engine.py", line 74, in search
    entity_metions = await self.entity_mention_extractor(query, **kwargs)
  File "C:\Users\Brooks.he\PycharmProjects\graphengine-alg-server-general\app\handlers\search_engine.py", line 36, in entity_mention_extractor
    mentions = await ENTITY_EXTRACTOR.extract(query, **kwargs)
  File "C:\Users\Brooks.he\PycharmProjects\graphengine-alg-server-general\app\algorithm\extractor.py", line 59, in extract
    mentions_lucene = await self.lucene_extractor.extract(
  File "C:\Users\Brooks.he\PycharmProjects\graphengine-alg-server-general\app\algorithm\lucene_extractor.py", line 117, in extract
    return await lucene_extractor.extract()
  File "C:\Users\Brooks.he\PycharmProjects\graphengine-alg-server-general\app\algorithm\lucene_extractor.py", line 25, in extract
    fulltext_indexes = await self._fulltext_indexes()
  File "C:\Users\Brooks.he\PycharmProjects\graphengine-alg-server-general\app\algorithm\lucene_extractor.py", line 34, in _fulltext_indexes
    indexes = await self.connector.execute(url)
  File "C:\Users\Brooks.he\PycharmProjects\graphengine-alg-server-general\venv\lib\site-packages\cognition\Connector.py", line 174, in execute
    response = await session.get(url, timeout=timeout, verify_ssl=False, headers=self.headers)
  File "C:\Users\Brooks.he\PycharmProjects\graphengine-alg-server-general\venv\lib\site-packages\aiohttp\client.py", line 527, in _request
    conn = await self._connector.connect(
  File "C:\Users\Brooks.he\PycharmProjects\graphengine-alg-server-general\venv\lib\site-packages\aiohttp\connector.py", line 537, in connect
    proto = await self._create_connection(req, traces, timeout)
  File "C:\Users\Brooks.he\PycharmProjects\graphengine-alg-server-general\venv\lib\site-packages\aiohttp\connector.py", line 894, in _create_connection
    _, proto = await self._create_direct_connection(req, traces, timeout)
  File "C:\Users\Brooks.he\PycharmProjects\graphengine-alg-server-general\venv\lib\site-packages\aiohttp\connector.py", line 1013, in _create_direct_connection
    raise ClientConnectorError(req.connection_key, exc) from exc
aiohttp.client_exceptions.ClientConnectorError: Cannot connect to host opensearch-master:9200 ssl:False [getaddrinfo failed]
[2022-08-26 17:56:08] [INFO] [process-19036] [thread-28148] [uvicorn.error-server.py:252] Shutting down
[2022-08-26 17:56:08] [INFO] [process-19036] [thread-28148] [uvicorn.error-on.py:64] Waiting for application shutdown.
[2022-08-26 17:56:08] [INFO] [process-19036] [thread-28148] [uvicorn.error-on.py:75] Application shutdown complete.
[2022-08-26 17:56:08] [INFO] [process-19036] [thread-28148] [uvicorn.error-server.py:85] Finished server process [19036]
[2022-08-26 17:56:09] [INFO] [process-27616] [thread-30744] [__main__-manager.py:29] Run api server...
[2022-08-26 17:56:09] [INFO] [process-27616] [thread-30744] [__main__-manager.py:31] bind ip is http://0.0.0.0:8080
[2022-08-26 17:56:10] [INFO] [process-27616] [thread-30744] [uvicorn.error-server.py:75] Started server process [27616]
[2022-08-26 17:56:10] [INFO] [process-27616] [thread-30744] [uvicorn.error-on.py:45] Waiting for application startup.
[2022-08-26 17:56:10] [INFO] [process-27616] [thread-30744] [uvicorn.error-on.py:59] Application startup complete.
[2022-08-26 17:56:10] [INFO] [process-27616] [thread-30744] [uvicorn.error-server.py:206] Uvicorn running on http://0.0.0.0:8080 (Press CTRL+C to quit)
[2022-08-26 17:56:14] [INFO] [process-27616] [thread-30744] [app.fastapi_app-fastapi_app.py:28] start call user_define_middleware
[2022-08-26 17:56:14] [ERROR] [process-27616] [thread-30744] [uvicorn.error-httptools_impl.py:375] Exception in ASGI application
Traceback (most recent call last):
  File "C:\Users\Brooks.he\PycharmProjects\graphengine-alg-server-general\venv\lib\site-packages\anyio\streams\memory.py", line 81, in receive
    return self.receive_nowait()
  File "C:\Users\Brooks.he\PycharmProjects\graphengine-alg-server-general\venv\lib\site-packages\anyio\streams\memory.py", line 76, in receive_nowait
    raise WouldBlock
anyio.WouldBlock

During handling of the above exception, another exception occurred:

Traceback (most recent call last):
  File "C:\Users\Brooks.he\PycharmProjects\graphengine-alg-server-general\venv\lib\site-packages\starlette\middleware\base.py", line 43, in call_next
    message = await recv_stream.receive()
  File "C:\Users\Brooks.he\PycharmProjects\graphengine-alg-server-general\venv\lib\site-packages\anyio\streams\memory.py", line 101, in receive
    raise EndOfStream
anyio.EndOfStream

During handling of the above exception, another exception occurred:

Traceback (most recent call last):
  File "C:\Users\Brooks.he\PycharmProjects\graphengine-alg-server-general\venv\lib\site-packages\uvicorn\protocols\http\httptools_impl.py", line 372, in run_asgi
    result = await app(self.scope, self.receive, self.send)
  File "C:\Users\Brooks.he\PycharmProjects\graphengine-alg-server-general\venv\lib\site-packages\uvicorn\middleware\proxy_headers.py", line 75, in __call__
    return await self.app(scope, receive, send)
  File "C:\Users\Brooks.he\PycharmProjects\graphengine-alg-server-general\venv\lib\site-packages\fastapi\applications.py", line 269, in __call__
    await super().__call__(scope, receive, send)
  File "C:\Users\Brooks.he\PycharmProjects\graphengine-alg-server-general\venv\lib\site-packages\starlette\applications.py", line 124, in __call__
    await self.middleware_stack(scope, receive, send)
  File "C:\Users\Brooks.he\PycharmProjects\graphengine-alg-server-general\venv\lib\site-packages\starlette\middleware\errors.py", line 184, in __call__
    raise exc
  File "C:\Users\Brooks.he\PycharmProjects\graphengine-alg-server-general\venv\lib\site-packages\starlette\middleware\errors.py", line 162, in __call__
    await self.app(scope, receive, _send)
  File "C:\Users\Brooks.he\PycharmProjects\graphengine-alg-server-general\venv\lib\site-packages\starlette\middleware\base.py", line 68, in __call__
    response = await self.dispatch_func(request, call_next)
  File "C:\Users\Brooks.he\PycharmProjects\graphengine-alg-server-general\app\fastapi_app.py", line 29, in user_define_middleware
    response = await call_next(request)
  File "C:\Users\Brooks.he\PycharmProjects\graphengine-alg-server-general\venv\lib\site-packages\starlette\middleware\base.py", line 46, in call_next
    raise app_exc
  File "C:\Users\Brooks.he\PycharmProjects\graphengine-alg-server-general\venv\lib\site-packages\starlette\middleware\base.py", line 36, in coro
    await self.app(scope, request.receive, send_stream.send)
  File "C:\Users\Brooks.he\PycharmProjects\graphengine-alg-server-general\venv\lib\site-packages\starlette\exceptions.py", line 93, in __call__
    raise exc
  File "C:\Users\Brooks.he\PycharmProjects\graphengine-alg-server-general\venv\lib\site-packages\starlette\exceptions.py", line 82, in __call__
    await self.app(scope, receive, sender)
  File "C:\Users\Brooks.he\PycharmProjects\graphengine-alg-server-general\venv\lib\site-packages\fastapi\middleware\asyncexitstack.py", line 21, in __call__
    raise e
  File "C:\Users\Brooks.he\PycharmProjects\graphengine-alg-server-general\venv\lib\site-packages\fastapi\middleware\asyncexitstack.py", line 18, in __call__
    await self.app(scope, receive, send)
  File "C:\Users\Brooks.he\PycharmProjects\graphengine-alg-server-general\venv\lib\site-packages\starlette\routing.py", line 670, in __call__
    await route.handle(scope, receive, send)
  File "C:\Users\Brooks.he\PycharmProjects\graphengine-alg-server-general\venv\lib\site-packages\starlette\routing.py", line 266, in handle
    await self.app(scope, receive, send)
  File "C:\Users\Brooks.he\PycharmProjects\graphengine-alg-server-general\venv\lib\site-packages\starlette\routing.py", line 65, in app
    response = await func(request)
  File "C:\Users\Brooks.he\PycharmProjects\graphengine-alg-server-general\venv\lib\site-packages\fastapi\routing.py", line 227, in app
    raw_response = await run_endpoint_function(
  File "C:\Users\Brooks.he\PycharmProjects\graphengine-alg-server-general\venv\lib\site-packages\fastapi\routing.py", line 160, in run_endpoint_function
    return await dependant.call(**values)
  File "C:\Users\Brooks.he\PycharmProjects\graphengine-alg-server-general\app\services\search.py", line 56, in post
    kg_id_to_search_engine, kg_id_to_search_kwargs = await init_search_engine(conf_info)
  File "C:\Users\Brooks.he\PycharmProjects\graphengine-alg-server-general\app\utils\init_search_engine.py", line 28, in init_search_engine
    ips=info["10.4.129.24"],
KeyError: '10.4.129.24'
[2022-08-26 17:56:42] [INFO] [process-27616] [thread-30744] [uvicorn.error-server.py:252] Shutting down
[2022-08-26 17:56:42] [INFO] [process-27616] [thread-30744] [uvicorn.error-on.py:64] Waiting for application shutdown.
[2022-08-26 17:56:42] [INFO] [process-27616] [thread-30744] [uvicorn.error-on.py:75] Application shutdown complete.
[2022-08-26 17:56:42] [INFO] [process-27616] [thread-30744] [uvicorn.error-server.py:85] Finished server process [27616]
[2022-08-26 17:56:43] [INFO] [process-9592] [thread-24208] [__main__-manager.py:29] Run api server...
[2022-08-26 17:56:43] [INFO] [process-9592] [thread-24208] [__main__-manager.py:31] bind ip is http://0.0.0.0:8080
[2022-08-26 17:56:44] [INFO] [process-9592] [thread-24208] [uvicorn.error-server.py:75] Started server process [9592]
[2022-08-26 17:56:44] [INFO] [process-9592] [thread-24208] [uvicorn.error-on.py:45] Waiting for application startup.
[2022-08-26 17:56:44] [INFO] [process-9592] [thread-24208] [uvicorn.error-on.py:59] Application startup complete.
[2022-08-26 17:56:44] [INFO] [process-9592] [thread-24208] [uvicorn.error-server.py:206] Uvicorn running on http://0.0.0.0:8080 (Press CTRL+C to quit)
[2022-08-26 17:56:45] [INFO] [process-9592] [thread-24208] [app.fastapi_app-fastapi_app.py:28] start call user_define_middleware
[2022-08-26 17:56:45] [ERROR] [process-9592] [thread-24208] [asyncio-base_events.py:1707] Exception in callback <TaskWakeupMethWrapper object at 0x00000265C445B280>(<Future finished result=None>)
handle: <Handle <TaskWakeupMethWrapper object at 0x00000265C445B280>(<Future finished result=None>)>
Traceback (most recent call last):
  File "C:\Python3.8\lib\asyncio\events.py", line 81, in _run
    self._context.run(self._callback, *self._args)
RuntimeError: Cannot enter into task <Task pending name='Task-1' coro=<Server.serve() running at C:\Users\Brooks.he\PycharmProjects\graphengine-alg-server-general\venv\lib\site-packages\uvicorn\server.py:80> wait_for=<Future finished result=None> cb=[_run_until_complete_cb() at C:\Python3.8\lib\asyncio\base_events.py:184]> while another task <Task pending name='starlette.middleware.base.BaseHTTPMiddleware.__call__.<locals>.call_next.<locals>.coro' coro=<BaseHTTPMiddleware.__call__.<locals>.call_next.<locals>.coro() running at C:\Users\Brooks.he\PycharmProjects\graphengine-alg-server-general\venv\lib\site-packages\starlette\middleware\base.py:36> cb=[TaskGroup._spawn.<locals>.task_done() at C:\Users\Brooks.he\PycharmProjects\graphengine-alg-server-general\venv\lib\site-packages\anyio\_backends\_asyncio.py:629]> is being executed.
[2022-08-26 17:56:45] [INFO] [process-9592] [thread-24208] [root-ConnectionPool.py:176] Get connection to ('10.4.131.25', 9669)
[2022-08-26 17:56:45] [INFO] [process-9592] [thread-24208] [root-ConnectionPool.py:176] Get connection to ('10.4.131.18', 9669)
[2022-08-26 17:56:45] [INFO] [process-9592] [thread-24208] [root-ConnectionPool.py:176] Get connection to ('10.4.133.125', 9669)
[2022-08-26 17:56:45] [INFO] [process-9592] [thread-24208] [app.fastapi_app-fastapi_app.py:30] end process user_define_middleware
[2022-08-26 18:12:32] [INFO] [process-9592] [thread-24208] [app.fastapi_app-fastapi_app.py:28] start call user_define_middleware
[2022-08-26 18:12:32] [INFO] [process-9592] [thread-24208] [app.fastapi_app-fastapi_app.py:30] end process user_define_middleware
