[2022-08-29 10:43:14] [INFO] [process-29428] [thread-30508] [__main__-manager.py:29] Run api server...
[2022-08-29 10:43:14] [INFO] [process-29428] [thread-30508] [__main__-manager.py:37] bind ip is http://0.0.0.0:8080
[2022-08-29 10:43:17] [INFO] [process-29428] [thread-30508] [uvicorn.error-server.py:75] Started server process [29428]
[2022-08-29 10:43:17] [INFO] [process-29428] [thread-30508] [uvicorn.error-on.py:45] Waiting for application startup.
[2022-08-29 10:43:17] [INFO] [process-29428] [thread-30508] [uvicorn.error-on.py:59] Application startup complete.
[2022-08-29 10:43:17] [INFO] [process-29428] [thread-30508] [uvicorn.error-server.py:206] Uvicorn running on http://0.0.0.0:8080 (Press CTRL+C to quit)
[2022-08-29 11:31:35] [INFO] [process-29428] [thread-30508] [app.fastapi_app-fastapi_app.py:28] start call user_define_middleware
[2022-08-29 11:31:35] [INFO] [process-29428] [thread-30508] [app.fastapi_app-fastapi_app.py:30] end process user_define_middleware
[2022-08-29 14:24:54] [INFO] [process-29428] [thread-30508] [app.fastapi_app-fastapi_app.py:28] start call user_define_middleware
[2022-08-29 14:24:54] [INFO] [process-29428] [thread-30508] [nebula3.logger-ConnectionPool.py:180] Get connection to ('10.4.128.147', 9669)
[2022-08-29 14:24:54] [INFO] [process-29428] [thread-30508] [nebula3.logger-ConnectionPool.py:164] Get connection to ('10.4.128.147', 9669)
[2022-08-29 14:24:54] [INFO] [process-29428] [thread-30508] [nebula3.logger-ConnectionPool.py:164] Get connection to ('10.4.128.147', 9669)
[2022-08-29 14:24:54] [INFO] [process-29428] [thread-30508] [app.fastapi_app-fastapi_app.py:30] end process user_define_middleware
[2022-08-29 14:27:26] [INFO] [process-29428] [thread-30508] [app.fastapi_app-fastapi_app.py:28] start call user_define_middleware
[2022-08-29 14:27:26] [INFO] [process-29428] [thread-30508] [nebula3.logger-ConnectionPool.py:180] Get connection to ('10.4.128.147', 9669)
[2022-08-29 14:27:26] [INFO] [process-29428] [thread-30508] [nebula3.logger-ConnectionPool.py:164] Get connection to ('10.4.128.147', 9669)
[2022-08-29 14:27:26] [INFO] [process-29428] [thread-30508] [nebula3.logger-ConnectionPool.py:164] Get connection to ('10.4.128.147', 9669)
[2022-08-29 14:27:27] [INFO] [process-29428] [thread-30508] [app.fastapi_app-fastapi_app.py:30] end process user_define_middleware
[2022-08-29 15:37:39] [INFO] [process-29428] [thread-30508] [app.fastapi_app-fastapi_app.py:28] start call user_define_middleware
[2022-08-29 15:37:41] [ERROR] [process-29428] [thread-30508] [uvicorn.error-httptools_impl.py:375] Exception in ASGI application
Traceback (most recent call last):
  File "C:\Users\Brooks.he\PycharmProjects\graphengine-alg-server-general\venv\lib\site-packages\aiomysql\connection.py", line 486, in _connect
    self._reader, self._writer = await \
  File "C:\Python3.8\lib\asyncio\tasks.py", line 455, in wait_for
    return await fut
  File "C:\Python3.8\lib\asyncio\streams.py", line 52, in open_connection
    transport, _ = await loop.create_connection(
  File "C:\Python3.8\lib\asyncio\base_events.py", line 1025, in create_connection
    raise exceptions[0]
  File "C:\Python3.8\lib\asyncio\base_events.py", line 1010, in create_connection
    sock = await self._connect_sock(
  File "C:\Python3.8\lib\asyncio\base_events.py", line 924, in _connect_sock
    await self.sock_connect(sock, address)
  File "C:\Python3.8\lib\asyncio\proactor_events.py", line 702, in sock_connect
    return await self._proactor.connect(sock, address)
  File "C:\Python3.8\lib\asyncio\tasks.py", line 349, in __wakeup
    future.result()
  File "C:\Python3.8\lib\asyncio\windows_events.py", line 808, in _poll
    value = callback(transferred, key, ov)
  File "C:\Python3.8\lib\asyncio\windows_events.py", line 595, in finish_connect
    ov.getresult()
ConnectionRefusedError: [WinError 1225] 远程计算机拒绝网络连接。

The above exception was the direct cause of the following exception:

Traceback (most recent call last):
  File "C:\Users\Brooks.he\PycharmProjects\graphengine-alg-server-general\venv\lib\site-packages\uvicorn\protocols\http\httptools_impl.py", line 372, in run_asgi
    result = await app(self.scope, self.receive, self.send)
  File "C:\Users\Brooks.he\PycharmProjects\graphengine-alg-server-general\venv\lib\site-packages\uvicorn\middleware\proxy_headers.py", line 75, in __call__
    return await self.app(scope, receive, send)
  File "C:\Users\Brooks.he\PycharmProjects\graphengine-alg-server-general\venv\lib\site-packages\fastapi\applications.py", line 269, in __call__
    await super().__call__(scope, receive, send)
  File "C:\Users\Brooks.he\PycharmProjects\graphengine-alg-server-general\venv\lib\site-packages\starlette\applications.py", line 124, in __call__
    await self.middleware_stack(scope, receive, send)
  File "C:\Users\Brooks.he\PycharmProjects\graphengine-alg-server-general\venv\lib\site-packages\starlette\middleware\errors.py", line 184, in __call__
    raise exc
  File "C:\Users\Brooks.he\PycharmProjects\graphengine-alg-server-general\venv\lib\site-packages\starlette\middleware\errors.py", line 162, in __call__
    await self.app(scope, receive, _send)
  File "C:\Users\Brooks.he\PycharmProjects\graphengine-alg-server-general\venv\lib\site-packages\starlette\middleware\base.py", line 68, in __call__
    response = await self.dispatch_func(request, call_next)
  File "C:\Users\Brooks.he\PycharmProjects\graphengine-alg-server-general\app\fastapi_app.py", line 29, in user_define_middleware
    response = await call_next(request)
  File "C:\Users\Brooks.he\PycharmProjects\graphengine-alg-server-general\venv\lib\site-packages\starlette\middleware\base.py", line 46, in call_next
    raise app_exc
  File "C:\Users\Brooks.he\PycharmProjects\graphengine-alg-server-general\venv\lib\site-packages\starlette\middleware\base.py", line 36, in coro
    await self.app(scope, request.receive, send_stream.send)
  File "C:\Users\Brooks.he\PycharmProjects\graphengine-alg-server-general\venv\lib\site-packages\starlette\exceptions.py", line 93, in __call__
    raise exc
  File "C:\Users\Brooks.he\PycharmProjects\graphengine-alg-server-general\venv\lib\site-packages\starlette\exceptions.py", line 82, in __call__
    await self.app(scope, receive, sender)
  File "C:\Users\Brooks.he\PycharmProjects\graphengine-alg-server-general\venv\lib\site-packages\fastapi\middleware\asyncexitstack.py", line 21, in __call__
    raise e
  File "C:\Users\Brooks.he\PycharmProjects\graphengine-alg-server-general\venv\lib\site-packages\fastapi\middleware\asyncexitstack.py", line 18, in __call__
    await self.app(scope, receive, send)
  File "C:\Users\Brooks.he\PycharmProjects\graphengine-alg-server-general\venv\lib\site-packages\starlette\routing.py", line 670, in __call__
    await route.handle(scope, receive, send)
  File "C:\Users\Brooks.he\PycharmProjects\graphengine-alg-server-general\venv\lib\site-packages\starlette\routing.py", line 266, in handle
    await self.app(scope, receive, send)
  File "C:\Users\Brooks.he\PycharmProjects\graphengine-alg-server-general\venv\lib\site-packages\starlette\routing.py", line 65, in app
    response = await func(request)
  File "C:\Users\Brooks.he\PycharmProjects\graphengine-alg-server-general\venv\lib\site-packages\fastapi\routing.py", line 227, in app
    raw_response = await run_endpoint_function(
  File "C:\Users\Brooks.he\PycharmProjects\graphengine-alg-server-general\venv\lib\site-packages\fastapi\routing.py", line 160, in run_endpoint_function
    return await dependant.call(**values)
  File "C:\Users\Brooks.he\PycharmProjects\graphengine-alg-server-general\app\services\search.py", line 55, in post
    conf_info = await get_adv_conf(ids=conf_content.kg_ids, ids_type="test", conf_content=conf_content.conf_content)
  File "C:\Users\Brooks.he\PycharmProjects\graphengine-alg-server-general\app\utils\get_adv_config.py", line 105, in get_adv_conf
    config_info = await mysql_connector.get(TEST_SQL.format(ids=ids))
  File "C:\Users\Brooks.he\PycharmProjects\graphengine-alg-server-general\app\utils\connector.py", line 13, in get
    async with self.pool.acquire() as con:
  File "C:\Users\Brooks.he\PycharmProjects\graphengine-alg-server-general\venv\lib\site-packages\aiomysql\utils.py", line 98, in __aenter__
    self._conn = await self._coro
  File "C:\Users\Brooks.he\PycharmProjects\graphengine-alg-server-general\venv\lib\site-packages\aiomysql\pool.py", line 135, in _acquire
    await self._fill_free_pool(True)
  File "C:\Users\Brooks.he\PycharmProjects\graphengine-alg-server-general\venv\lib\site-packages\aiomysql\pool.py", line 167, in _fill_free_pool
    conn = await connect(echo=self._echo, loop=self._loop,
  File "C:\Users\Brooks.he\PycharmProjects\graphengine-alg-server-general\venv\lib\site-packages\aiomysql\connection.py", line 75, in _connect
    await conn._connect()
  File "C:\Users\Brooks.he\PycharmProjects\graphengine-alg-server-general\venv\lib\site-packages\aiomysql\connection.py", line 521, in _connect
    raise OperationalError(2003,
pymysql.err.OperationalError: (2003, "Can't connect to MySQL server on '10.4.106.255'")
[2022-08-29 15:37:53] [INFO] [process-29428] [thread-30508] [app.fastapi_app-fastapi_app.py:28] start call user_define_middleware
[2022-08-29 15:37:55] [ERROR] [process-29428] [thread-30508] [uvicorn.error-httptools_impl.py:375] Exception in ASGI application
Traceback (most recent call last):
  File "C:\Users\Brooks.he\PycharmProjects\graphengine-alg-server-general\venv\lib\site-packages\aiomysql\connection.py", line 486, in _connect
    self._reader, self._writer = await \
  File "C:\Python3.8\lib\asyncio\tasks.py", line 455, in wait_for
    return await fut
  File "C:\Python3.8\lib\asyncio\streams.py", line 52, in open_connection
    transport, _ = await loop.create_connection(
  File "C:\Python3.8\lib\asyncio\base_events.py", line 1025, in create_connection
    raise exceptions[0]
  File "C:\Python3.8\lib\asyncio\base_events.py", line 1010, in create_connection
    sock = await self._connect_sock(
  File "C:\Python3.8\lib\asyncio\base_events.py", line 924, in _connect_sock
    await self.sock_connect(sock, address)
  File "C:\Python3.8\lib\asyncio\proactor_events.py", line 702, in sock_connect
    return await self._proactor.connect(sock, address)
  File "C:\Python3.8\lib\asyncio\tasks.py", line 349, in __wakeup
    future.result()
  File "C:\Python3.8\lib\asyncio\windows_events.py", line 808, in _poll
    value = callback(transferred, key, ov)
  File "C:\Python3.8\lib\asyncio\windows_events.py", line 595, in finish_connect
    ov.getresult()
ConnectionRefusedError: [WinError 1225] 远程计算机拒绝网络连接。

The above exception was the direct cause of the following exception:

Traceback (most recent call last):
  File "C:\Users\Brooks.he\PycharmProjects\graphengine-alg-server-general\venv\lib\site-packages\uvicorn\protocols\http\httptools_impl.py", line 372, in run_asgi
    result = await app(self.scope, self.receive, self.send)
  File "C:\Users\Brooks.he\PycharmProjects\graphengine-alg-server-general\venv\lib\site-packages\uvicorn\middleware\proxy_headers.py", line 75, in __call__
    return await self.app(scope, receive, send)
  File "C:\Users\Brooks.he\PycharmProjects\graphengine-alg-server-general\venv\lib\site-packages\fastapi\applications.py", line 269, in __call__
    await super().__call__(scope, receive, send)
  File "C:\Users\Brooks.he\PycharmProjects\graphengine-alg-server-general\venv\lib\site-packages\starlette\applications.py", line 124, in __call__
    await self.middleware_stack(scope, receive, send)
  File "C:\Users\Brooks.he\PycharmProjects\graphengine-alg-server-general\venv\lib\site-packages\starlette\middleware\errors.py", line 184, in __call__
    raise exc
  File "C:\Users\Brooks.he\PycharmProjects\graphengine-alg-server-general\venv\lib\site-packages\starlette\middleware\errors.py", line 162, in __call__
    await self.app(scope, receive, _send)
  File "C:\Users\Brooks.he\PycharmProjects\graphengine-alg-server-general\venv\lib\site-packages\starlette\middleware\base.py", line 68, in __call__
    response = await self.dispatch_func(request, call_next)
  File "C:\Users\Brooks.he\PycharmProjects\graphengine-alg-server-general\app\fastapi_app.py", line 29, in user_define_middleware
    response = await call_next(request)
  File "C:\Users\Brooks.he\PycharmProjects\graphengine-alg-server-general\venv\lib\site-packages\starlette\middleware\base.py", line 46, in call_next
    raise app_exc
  File "C:\Users\Brooks.he\PycharmProjects\graphengine-alg-server-general\venv\lib\site-packages\starlette\middleware\base.py", line 36, in coro
    await self.app(scope, request.receive, send_stream.send)
  File "C:\Users\Brooks.he\PycharmProjects\graphengine-alg-server-general\venv\lib\site-packages\starlette\exceptions.py", line 93, in __call__
    raise exc
  File "C:\Users\Brooks.he\PycharmProjects\graphengine-alg-server-general\venv\lib\site-packages\starlette\exceptions.py", line 82, in __call__
    await self.app(scope, receive, sender)
  File "C:\Users\Brooks.he\PycharmProjects\graphengine-alg-server-general\venv\lib\site-packages\fastapi\middleware\asyncexitstack.py", line 21, in __call__
    raise e
  File "C:\Users\Brooks.he\PycharmProjects\graphengine-alg-server-general\venv\lib\site-packages\fastapi\middleware\asyncexitstack.py", line 18, in __call__
    await self.app(scope, receive, send)
  File "C:\Users\Brooks.he\PycharmProjects\graphengine-alg-server-general\venv\lib\site-packages\starlette\routing.py", line 670, in __call__
    await route.handle(scope, receive, send)
  File "C:\Users\Brooks.he\PycharmProjects\graphengine-alg-server-general\venv\lib\site-packages\starlette\routing.py", line 266, in handle
    await self.app(scope, receive, send)
  File "C:\Users\Brooks.he\PycharmProjects\graphengine-alg-server-general\venv\lib\site-packages\starlette\routing.py", line 65, in app
    response = await func(request)
  File "C:\Users\Brooks.he\PycharmProjects\graphengine-alg-server-general\venv\lib\site-packages\fastapi\routing.py", line 227, in app
    raw_response = await run_endpoint_function(
  File "C:\Users\Brooks.he\PycharmProjects\graphengine-alg-server-general\venv\lib\site-packages\fastapi\routing.py", line 160, in run_endpoint_function
    return await dependant.call(**values)
  File "C:\Users\Brooks.he\PycharmProjects\graphengine-alg-server-general\app\services\search.py", line 22, in get
    conf_info = await get_adv_conf(ids=conf_ids, ids_type="conf_id")
  File "C:\Users\Brooks.he\PycharmProjects\graphengine-alg-server-general\app\utils\get_adv_config.py", line 103, in get_adv_conf
    config_info = await mysql_connector.get(SQL_BY_CONF_ID.format(ids=ids))
  File "C:\Users\Brooks.he\PycharmProjects\graphengine-alg-server-general\app\utils\connector.py", line 13, in get
    async with self.pool.acquire() as con:
  File "C:\Users\Brooks.he\PycharmProjects\graphengine-alg-server-general\venv\lib\site-packages\aiomysql\utils.py", line 98, in __aenter__
    self._conn = await self._coro
  File "C:\Users\Brooks.he\PycharmProjects\graphengine-alg-server-general\venv\lib\site-packages\aiomysql\pool.py", line 135, in _acquire
    await self._fill_free_pool(True)
  File "C:\Users\Brooks.he\PycharmProjects\graphengine-alg-server-general\venv\lib\site-packages\aiomysql\pool.py", line 167, in _fill_free_pool
    conn = await connect(echo=self._echo, loop=self._loop,
  File "C:\Users\Brooks.he\PycharmProjects\graphengine-alg-server-general\venv\lib\site-packages\aiomysql\connection.py", line 75, in _connect
    await conn._connect()
  File "C:\Users\Brooks.he\PycharmProjects\graphengine-alg-server-general\venv\lib\site-packages\aiomysql\connection.py", line 521, in _connect
    raise OperationalError(2003,
pymysql.err.OperationalError: (2003, "Can't connect to MySQL server on '10.4.106.255'")
[2022-08-29 17:35:32] [INFO] [process-29428] [thread-30508] [app.fastapi_app-fastapi_app.py:28] start call user_define_middleware
[2022-08-29 17:35:33] [INFO] [process-29428] [thread-30508] [nebula3.logger-ConnectionPool.py:180] Get connection to ('10.4.128.147', 9669)
[2022-08-29 17:35:33] [INFO] [process-29428] [thread-30508] [nebula3.logger-ConnectionPool.py:164] Get connection to ('10.4.128.147', 9669)
[2022-08-29 17:35:33] [INFO] [process-29428] [thread-30508] [nebula3.logger-ConnectionPool.py:164] Get connection to ('10.4.128.147', 9669)
[2022-08-29 17:35:33] [INFO] [process-29428] [thread-30508] [app.fastapi_app-fastapi_app.py:30] end process user_define_middleware
