# Translations template for PROJECT.
# Copyright (C) 2022 ORGANIZATION
# This file is distributed under the same license as the PROJECT project.
# FIRST AUTHOR <EMAIL@ADDRESS>, 2022.
#
#, fuzzy
msgid ""
msgstr ""
"Project-Id-Version: PROJECT VERSION\n"
"Report-Msgid-Bugs-To: EMAIL@ADDRESS\n"
"POT-Creation-Date: 2022-10-13 16:52+0800\n"
"PO-Revision-Date: YEAR-MO-DA HO:MI+ZONE\n"
"Last-Translator: FULL NAME <EMAIL@ADDRESS>\n"
"Language-Team: LANGUAGE <LL@li.org>\n"
"MIME-Version: 1.0\n"
"Content-Type: text/plain; charset=utf-8\n"
"Content-Transfer-Encoding: 8bit\n"
"Generated-By: Babel 2.10.3\n"

#: common/errorcode/errors/graph_error.py:8
#: common/errorcode/errors/graph_error.py:115
#: common/errorcode/errors/graph_error.py:127
#: common/errorcode/errors/graph_error.py:133
msgid "Parameter [arg] Error."
msgstr ""

#: common/errorcode/errors/graph_error.py:9
#: common/errorcode/errors/graph_error.py:21
#: common/errorcode/errors/graph_error.py:27
#: common/errorcode/errors/graph_error.py:51
#: common/errorcode/errors/graph_error.py:63
#: common/errorcode/errors/graph_error.py:75
#: common/errorcode/errors/graph_error.py:87
#: common/errorcode/errors/graph_error.py:93
#: common/errorcode/errors/graph_error.py:105
#: common/errorcode/errors/graph_error.py:111
#: common/errorcode/errors/lexicon_error.py:16
#: common/errorcode/errors/lexicon_error.py:22
#: common/errorcode/errors/lexicon_error.py:28
#: common/errorcode/errors/lexicon_error.py:70
#: common/errorcode/errors/lexicon_error.py:76
#: common/errorcode/errors/lexicon_error.py:83
#: common/errorcode/errors/lexicon_error.py:89
#: common/errorcode/errors/lexicon_error.py:96
#: common/errorcode/errors/lexicon_error.py:102
#: common/errorcode/errors/lexicon_error.py:109
#: common/errorcode/errors/lexicon_error.py:115
#: common/errorcode/errors/lexicon_error.py:140
#: common/errorcode/errors/lexicon_error.py:146
#: common/errorcode/errors/lexicon_error.py:153
#: common/errorcode/errors/lexicon_error.py:159
#: common/errorcode/errors/lexicon_error.py:165
#: common/errorcode/errors/lexicon_error.py:177
#: common/errorcode/errors/lexicon_error.py:190
#: common/errorcode/errors/lexicon_error.py:196
#: common/errorcode/errors/lexicon_error.py:216
#: common/errorcode/errors/lexicon_error.py:222
#: common/errorcode/errors/lexicon_error.py:228
#: common/errorcode/errors/lexicon_error.py:236
#: common/errorcode/errors/lexicon_error.py:242
#: common/errorcode/errors/lexicon_error.py:249
#: common/errorcode/errors/lexicon_error.py:255
#: common/errorcode/errors/lexicon_error.py:274
#: common/errorcode/errors/lexicon_error.py:288
#: common/errorcode/errors/lexicon_error.py:294
#: common/errorcode/errors/lexicon_error.py:301
#: common/errorcode/errors/lexicon_error.py:307
#: common/errorcode/errors/lexicon_error.py:368
#: common/errorcode/errors/lexicon_error.py:374
msgid "Please check your parameter again."
msgstr ""

#: common/errorcode/errors/graph_error.py:14
#: common/errorcode/errors/graph_error.py:56
#: common/errorcode/errors/graph_error.py:80
#: common/errorcode/errors/graph_error.py:98
#: common/errorcode/errors/graph_error.py:122
#: common/errorcode/errors/graph_error.py:140
msgid "[cause]"
msgstr ""

#: common/errorcode/errors/graph_error.py:15
#: common/errorcode/errors/graph_error.py:57
#: common/errorcode/errors/graph_error.py:81
#: common/errorcode/errors/graph_error.py:99
#: common/errorcode/errors/graph_error.py:123
#: common/errorcode/errors/graph_error.py:141
#: common/errorcode/errors/intelligence_error.py:9
#: common/errorcode/errors/intelligence_error.py:15
#: common/errorcode/errors/intelligence_error.py:45
#: common/errorcode/errors/intelligence_error.py:51
#: common/errorcode/errors/intelligence_error.py:57
#: common/errorcode/errors/intelligence_error.py:63
msgid "Please contact the developers."
msgstr ""

#: common/errorcode/errors/graph_error.py:19
#: common/errorcode/errors/graph_error.py:20
msgid "graphid [graphid] not exists."
msgstr ""

#: common/errorcode/errors/graph_error.py:25
msgid "key type error"
msgstr ""

#: common/errorcode/errors/graph_error.py:26
msgid "key should be list of string"
msgstr ""

#: common/errorcode/errors/graph_error.py:31
#: common/errorcode/errors/graph_error.py:32
msgid "graphdb id [graphdb_id] not exists"
msgstr ""

#: common/errorcode/errors/graph_error.py:33
msgid "please config your graphdb again."
msgstr ""

#: common/errorcode/errors/graph_error.py:43
msgid "these keys are not supported: [unsupported_key]"
msgstr ""

#: common/errorcode/errors/graph_error.py:44
msgid "some keys are not supported."
msgstr ""

#: common/errorcode/errors/graph_error.py:45
msgid "please check your parameter key again."
msgstr ""

#: common/errorcode/errors/graph_error.py:50
#: common/errorcode/errors/graph_error.py:74
#: common/errorcode/errors/graph_error.py:92
msgid "argument [arg] error"
msgstr ""

#: common/errorcode/errors/graph_error.py:61
#: common/errorcode/errors/graph_error.py:62
#: common/errorcode/errors/graph_error.py:85
#: common/errorcode/errors/graph_error.py:86
#: common/errorcode/errors/graph_error.py:103
#: common/errorcode/errors/graph_error.py:104
msgid "graph id [graphid] not exists"
msgstr ""

#: common/errorcode/errors/graph_error.py:67
#: common/errorcode/errors/graph_error.py:68
msgid "ontology id [otl_id] not exists"
msgstr ""

#: common/errorcode/errors/graph_error.py:69
msgid "Please config the ontology."
msgstr ""

#: common/errorcode/errors/graph_error.py:109
#: common/errorcode/errors/graph_error.py:110
msgid "[class_type] [name] not exists"
msgstr ""

#: common/errorcode/errors/graph_error.py:116
#: common/errorcode/errors/graph_error.py:128
#: common/errorcode/errors/graph_error.py:134
msgid "parameter [arg] not exists or invalid"
msgstr ""

#: common/errorcode/errors/graph_error.py:117
#: common/errorcode/errors/graph_error.py:129
#: common/errorcode/errors/graph_error.py:135
msgid "please ensure parameter [arg] exists and valid"
msgstr ""

#: common/errorcode/errors/graphdb_error.py:9
#: common/errorcode/errors/graphdb_error.py:33
msgid "Please check whether the OrientDB request information is correct."
msgstr ""

#: common/errorcode/errors/graphdb_error.py:15
#: common/errorcode/errors/graphdb_error.py:39
#: common/errorcode/errors/graphdb_error.py:45
msgid "Please check whether the Nebula request information is correct."
msgstr ""

#: common/errorcode/errors/graphdb_error.py:21
msgid "Please check whether your GraphDB service is running normally."
msgstr ""

#: common/errorcode/errors/graphdb_error.py:27
msgid "Please check whether your DB name is correct."
msgstr ""

#: common/errorcode/errors/intelligence_error.py:19
#: common/errorcode/errors/intelligence_error.py:20
msgid "knowledge graph is waiting build, please calculate after building"
msgstr ""

#: common/errorcode/errors/intelligence_error.py:21
#: common/errorcode/errors/intelligence_error.py:27
#: common/errorcode/errors/intelligence_error.py:33
#: common/errorcode/errors/intelligence_error.py:39
#: common/errorcode/errors/intelligence_error.py:69
msgid "Please check graph status"
msgstr ""

#: common/errorcode/errors/intelligence_error.py:25
#: common/errorcode/errors/intelligence_error.py:26
msgid "knowledge graph is building, please calculate after building"
msgstr ""

#: common/errorcode/errors/intelligence_error.py:31
#: common/errorcode/errors/intelligence_error.py:32
msgid "knowledge graph is configuring build, please calculate after building"
msgstr ""

#: common/errorcode/errors/intelligence_error.py:37
#: common/errorcode/errors/intelligence_error.py:38
msgid ""
"knowledge graph store in NebulaGraph, if you need intelligence score, "
"please calculate after building successfully"
msgstr ""

#: common/errorcode/errors/intelligence_error.py:43
msgid "call async task service error"
msgstr ""

#: common/errorcode/errors/intelligence_error.py:44
#: common/errorcode/errors/intelligence_error.py:50
#: common/errorcode/errors/intelligence_error.py:56
#: common/errorcode/errors/intelligence_error.py:62
#: common/errorcode/errors/network_error.py:8
#: common/errorcode/errors/network_error.py:14
msgid "[detail]"
msgstr ""

#: common/errorcode/errors/intelligence_error.py:49
msgid "async task service internal error"
msgstr ""

#: common/errorcode/errors/intelligence_error.py:55
msgid "graph intelligence info query error"
msgstr ""

#: common/errorcode/errors/intelligence_error.py:61
msgid "network intelligence info query error"
msgstr ""

#: common/errorcode/errors/intelligence_error.py:67
#: common/errorcode/errors/intelligence_error.py:68
msgid ""
"knowledge graph status invalid, please calculate after building "
"successfully"
msgstr ""

#: common/errorcode/errors/lexicon_error.py:9
msgid "Please check the database connection."
msgstr ""

#: common/errorcode/errors/lexicon_error.py:21
msgid ""
"The specified knowledge_id [knowledge_id] does not exist, lexicon "
"creation failed!"
msgstr ""

#: common/errorcode/errors/lexicon_error.py:27
#: common/errorcode/errors/lexicon_error.py:227
msgid ""
"Lexicon name [lexicon_name] already exists and cannot be created "
"repeatedly."
msgstr ""

#: common/errorcode/errors/lexicon_error.py:33
#: common/errorcode/errors/lexicon_error.py:312
msgid "[ErrorDetails]"
msgstr ""

#: common/errorcode/errors/lexicon_error.py:34
msgid "Please check the type, size and content format of the uploaded file."
msgstr ""

#: common/errorcode/errors/lexicon_error.py:39
#: common/errorcode/errors/lexicon_error.py:324
msgid "Only one file can be selected at most."
msgstr ""

#: common/errorcode/errors/lexicon_error.py:40
#: common/errorcode/errors/lexicon_error.py:46
#: common/errorcode/errors/lexicon_error.py:325
#: common/errorcode/errors/lexicon_error.py:331
#: common/errorcode/errors/lexicon_error.py:349
msgid "Please select upload file again."
msgstr ""

#: common/errorcode/errors/lexicon_error.py:45
#: common/errorcode/errors/lexicon_error.py:330
msgid "The file format only supports txt and CSV."
msgstr ""

#: common/errorcode/errors/lexicon_error.py:51
#: common/errorcode/errors/lexicon_error.py:336
msgid "File content format error."
msgstr ""

#: common/errorcode/errors/lexicon_error.py:52
#: common/errorcode/errors/lexicon_error.py:337
msgid ""
"Please check the content and format of the document according to the "
"template."
msgstr ""

#: common/errorcode/errors/lexicon_error.py:57
#: common/errorcode/errors/lexicon_error.py:342
msgid "The file only supports UTF-8 encoding."
msgstr ""

#: common/errorcode/errors/lexicon_error.py:58
#: common/errorcode/errors/lexicon_error.py:343
msgid "Please confirm the file code and reselect the file."
msgstr ""

#: common/errorcode/errors/lexicon_error.py:63
#: common/errorcode/errors/lexicon_error.py:354
msgid "The amount of uploaded file data exceeds."
msgstr ""

#: common/errorcode/errors/lexicon_error.py:64
#: common/errorcode/errors/lexicon_error.py:355
msgid ""
"The uploaded file must be less than 10M and the number of lines must be "
"less than 350000."
msgstr ""

#: common/errorcode/errors/lexicon_error.py:75
msgid ""
"The specified knowledge_id [knowledge_id] does not exist, get labels "
"failed!"
msgstr ""

#: common/errorcode/errors/lexicon_error.py:88
msgid ""
"The specified knowledge_id [knowledge_id] does not exist, get lexicon "
"failed!"
msgstr ""

#: common/errorcode/errors/lexicon_error.py:101
msgid "The specified lexicon id [lexicon_id] does not exist, get lexicon failed!"
msgstr ""

#: common/errorcode/errors/lexicon_error.py:114
#: common/errorcode/errors/lexicon_error.py:139
#: common/errorcode/errors/lexicon_error.py:158
#: common/errorcode/errors/lexicon_error.py:195
#: common/errorcode/errors/lexicon_error.py:221
#: common/errorcode/errors/lexicon_error.py:241
#: common/errorcode/errors/lexicon_error.py:254
#: common/errorcode/errors/lexicon_error.py:293
#: common/errorcode/errors/lexicon_error.py:306
#: common/errorcode/errors/lexicon_error.py:373
msgid "The specified lexicon id [lexicon_id] does not exist."
msgstr ""

#: common/errorcode/errors/lexicon_error.py:120
msgid "The format of the new data [data] does not match the original data"
msgstr ""

#: common/errorcode/errors/lexicon_error.py:121
#: common/errorcode/errors/lexicon_error.py:127
#: common/errorcode/errors/lexicon_error.py:171
#: common/errorcode/errors/lexicon_error.py:202
#: common/errorcode/errors/lexicon_error.py:319
msgid "Please check lexicon format again."
msgstr ""

#: common/errorcode/errors/lexicon_error.py:126
msgid "The newly added word [data] already exists."
msgstr ""

#: common/errorcode/errors/lexicon_error.py:132
msgid "lexicon [lexicon_id] status is running, cannot insert."
msgstr ""

#: common/errorcode/errors/lexicon_error.py:133
#: common/errorcode/errors/lexicon_error.py:183
#: common/errorcode/errors/lexicon_error.py:208
#: common/errorcode/errors/lexicon_error.py:267
#: common/errorcode/errors/lexicon_error.py:361
msgid "lexicon status is running, please make sure lexicon status is correct."
msgstr ""

#: common/errorcode/errors/lexicon_error.py:164
msgid "The specified lexicon word [lexicon_word] does not exist."
msgstr ""

#: common/errorcode/errors/lexicon_error.py:170
msgid "New data [new_info] and original data [old_info] fields are inconsistent."
msgstr ""

#: common/errorcode/errors/lexicon_error.py:176
msgid "The modified word [lexicon_word] already exists."
msgstr ""

#: common/errorcode/errors/lexicon_error.py:182
msgid "lexicon [lexicon_id] status is running, cannot edit word."
msgstr ""

#: common/errorcode/errors/lexicon_error.py:201
msgid "There is no deleted data [delete_data] in the specified lexicon."
msgstr ""

#: common/errorcode/errors/lexicon_error.py:207
msgid "lexicon [lexicon_id] status is running, cannot delete word."
msgstr ""

#: common/errorcode/errors/lexicon_error.py:266
msgid "lexicon [lexicon_id] status is running, cannot export."
msgstr ""

#: common/errorcode/errors/lexicon_error.py:280
msgid "Please see the error prompt for details."
msgstr ""

#: common/errorcode/errors/lexicon_error.py:313
msgid "Please check the type and size of the uploaded file."
msgstr ""

#: common/errorcode/errors/lexicon_error.py:318
msgid "New data and original data fields are inconsistent"
msgstr ""

#: common/errorcode/errors/lexicon_error.py:348
msgid "Select at least one file."
msgstr ""

#: common/errorcode/errors/lexicon_error.py:360
msgid "lexicon [lexicon_id] status is running, cannot import words."
msgstr ""

#: common/errorcode/errors/network_error.py:7
msgid "Parameters Error!"
msgstr ""

#: common/errorcode/errors/network_error.py:9
#: common/errorcode/errors/network_error.py:15
msgid "Please check your parameters."
msgstr ""

#: common/errorcode/errors/network_error.py:13
msgid "[description]"
msgstr ""

